{"uid":"4b4757e66a1912dae1a509f688f20b0f","name":"categories","children":[{"name":"Test defects","children":[{"name":"urllib3.exceptions.MaxRetryError: HTTPConnectionPool(host='127.0.0.1', port=4723): Max retries exceeded with url: /session (Caused by NewConnectionError('<urllib3.connection.HTTPConnection object at 0x0000021583F762C0>: Failed to establish a new connection: [WinError 10061] No connection could be made because the target machine actively refused it'))","children":[{"name":"test_changeProfileInfo","uid":"a98f12fd812f7e93","parentUid":"fd19d027523db35b7a29c448691eb015","status":"broken","time":{"start":1730742427183,"stop":1730742427183,"duration":0},"flaky":false,"newFailed":false,"newPassed":false,"newBroken":false,"retriesCount":25,"retriesStatusChange":true,"parameters":[],"tags":["order(2)","@pytest.mark.usefixtures('on_failure', 'appium_driver')"]}],"uid":"fd19d027523db35b7a29c448691eb015"},{"name":"urllib3.exceptions.MaxRetryError: HTTPConnectionPool(host='127.0.0.1', port=4723): Max retries exceeded with url: /session (Caused by NewConnectionError('<urllib3.connection.HTTPConnection object at 0x0000021583F979B0>: Failed to establish a new connection: [WinError 10061] No connection could be made because the target machine actively refused it'))","children":[{"name":"test_login_HAPPY_PATH","uid":"dce8818af7d669b0","parentUid":"84125cc35f3794a3a00fe0f8a2c01b57","status":"broken","time":{"start":1730742435687,"stop":1730742435687,"duration":0},"flaky":false,"newFailed":false,"newPassed":false,"newBroken":false,"retriesCount":10,"retriesStatusChange":true,"parameters":[],"tags":["order(1)","@pytest.mark.usefixtures('on_failure', 'appium_driver')"]}],"uid":"84125cc35f3794a3a00fe0f8a2c01b57"},{"name":"urllib3.exceptions.MaxRetryError: HTTPConnectionPool(host='127.0.0.1', port=4723): Max retries exceeded with url: /session (Caused by NewConnectionError('<urllib3.connection.HTTPConnection object at 0x0000021584270380>: Failed to establish a new connection: [WinError 10061] No connection could be made because the target machine actively refused it'))","children":[{"name":"test_logout_from_home_HAPPY_PATH","uid":"41b538512b03bdca","parentUid":"b3e56e513e639bc135579fcc9f881135","status":"broken","time":{"start":1730742443983,"stop":1730742443983,"duration":0},"flaky":false,"newFailed":false,"newPassed":false,"newBroken":false,"retriesCount":10,"retriesStatusChange":true,"parameters":[],"tags":["order(3)","@pytest.mark.usefixtures('on_failure', 'appium_driver')"]}],"uid":"b3e56e513e639bc135579fcc9f881135"}],"uid":"bdbf199525818fae7a8651db9eafe741"}]}